INFO:root: 2021-08-19 18:53:03 All credentials have been retrieved
INFO:root: 2021-08-19 19:39:49 All credentials have been retrieved
INFO:root: 2021-08-19 19:40:32 Login Successful
INFO:root: 2021-08-19 19:41:52 All credentials have been retrieved
INFO:root: 2021-08-19 19:42:09 Login Successful
INFO:werkzeug: * Running on http://127.0.0.1:5000/ (Press CTRL+C to quit)
INFO:root: 2021-08-19 19:42:30 Service Started
INFO:root: 2021-08-19 19:43:07 All credentials have been retrieved
INFO:root: 2021-08-19 19:43:20 Login Successful
INFO:werkzeug: * Running on http://127.0.0.1:5000/ (Press CTRL+C to quit)
INFO:root: 2021-08-19 19:43:24 Service Started
INFO:root: 2021-08-19 19:46:32 All credentials have been retrieved
INFO:root: 2021-08-19 19:46:51 Login Successful
INFO:werkzeug: * Running on http://127.0.0.1:5000/ (Press CTRL+C to quit)
INFO:root: 2021-08-19 19:46:54 Service Started
INFO:werkzeug:127.0.0.1 - - [19/Aug/2021 19:47:33] "GET /shutdown HTTP/1.1" 200 -
INFO:root: 2021-08-19 19:47:35 Service has stopped
INFO:root: 2021-08-19 19:48:21 All credentials have been retrieved
INFO:root: 2021-08-19 19:48:40 Login Successful
INFO:werkzeug: * Running on http://127.0.0.1:5000/ (Press CTRL+C to quit)
INFO:root: 2021-08-19 19:48:50 Service Started
ERROR:filesharing.app:Exception on /send_request [POST]
Traceback (most recent call last):
  File "/Users/yonatancipriani/Library/Caches/pypoetry/virtualenvs/filesharing-K7xW8qzq-py3.9/lib/python3.9/site-packages/pymongo/srv_resolver.py", line 88, in _resolve_uri
    results = _resolve('_mongodb._tcp.' + self.__fqdn, 'SRV',
  File "/Users/yonatancipriani/Library/Caches/pypoetry/virtualenvs/filesharing-K7xW8qzq-py3.9/lib/python3.9/site-packages/pymongo/srv_resolver.py", line 46, in _resolve
    return resolver.resolve(*args, **kwargs)
  File "/Users/yonatancipriani/Library/Caches/pypoetry/virtualenvs/filesharing-K7xW8qzq-py3.9/lib/python3.9/site-packages/dns/resolver.py", line 1305, in resolve
    return get_default_resolver().resolve(qname, rdtype, rdclass, tcp, source,
  File "/Users/yonatancipriani/Library/Caches/pypoetry/virtualenvs/filesharing-K7xW8qzq-py3.9/lib/python3.9/site-packages/dns/resolver.py", line 1176, in resolve
    timeout = self._compute_timeout(start, lifetime)
  File "/Users/yonatancipriani/Library/Caches/pypoetry/virtualenvs/filesharing-K7xW8qzq-py3.9/lib/python3.9/site-packages/dns/resolver.py", line 997, in _compute_timeout
    raise Timeout(timeout=duration)
dns.exception.Timeout: The DNS operation timed out after 20.002588987350464 seconds

During handling of the above exception, another exception occurred:

Traceback (most recent call last):
  File "/Users/yonatancipriani/Library/Caches/pypoetry/virtualenvs/filesharing-K7xW8qzq-py3.9/lib/python3.9/site-packages/flask/app.py", line 2070, in wsgi_app
    response = self.full_dispatch_request()
  File "/Users/yonatancipriani/Library/Caches/pypoetry/virtualenvs/filesharing-K7xW8qzq-py3.9/lib/python3.9/site-packages/flask/app.py", line 1515, in full_dispatch_request
    rv = self.handle_user_exception(e)
  File "/Users/yonatancipriani/Library/Caches/pypoetry/virtualenvs/filesharing-K7xW8qzq-py3.9/lib/python3.9/site-packages/flask_restful/__init__.py", line 271, in error_router
    return original_handler(e)
  File "/Users/yonatancipriani/Library/Caches/pypoetry/virtualenvs/filesharing-K7xW8qzq-py3.9/lib/python3.9/site-packages/flask/app.py", line 1513, in full_dispatch_request
    rv = self.dispatch_request()
  File "/Users/yonatancipriani/Library/Caches/pypoetry/virtualenvs/filesharing-K7xW8qzq-py3.9/lib/python3.9/site-packages/flask/app.py", line 1499, in dispatch_request
    return self.ensure_sync(self.view_functions[rule.endpoint])(**req.view_args)
  File "/Users/yonatancipriani/PycharmProjects/fileSharing/filesharing/app.py", line 57, in send_request
    dal = mongodbDAL(request_type)
  File "/Users/yonatancipriani/PycharmProjects/fileSharing/filesharing/db/mongodbDAL.py", line 11, in __init__
    self.client = MongoClient(self.connection_string)
  File "/Users/yonatancipriani/Library/Caches/pypoetry/virtualenvs/filesharing-K7xW8qzq-py3.9/lib/python3.9/site-packages/pymongo/mongo_client.py", line 670, in __init__
    res = uri_parser.parse_uri(
  File "/Users/yonatancipriani/Library/Caches/pypoetry/virtualenvs/filesharing-K7xW8qzq-py3.9/lib/python3.9/site-packages/pymongo/uri_parser.py", line 524, in parse_uri
    nodes = dns_resolver.get_hosts()
  File "/Users/yonatancipriani/Library/Caches/pypoetry/virtualenvs/filesharing-K7xW8qzq-py3.9/lib/python3.9/site-packages/pymongo/srv_resolver.py", line 118, in get_hosts
    _, nodes = self._get_srv_response_and_hosts(True)
  File "/Users/yonatancipriani/Library/Caches/pypoetry/virtualenvs/filesharing-K7xW8qzq-py3.9/lib/python3.9/site-packages/pymongo/srv_resolver.py", line 99, in _get_srv_response_and_hosts
    results = self._resolve_uri(encapsulate_errors)
  File "/Users/yonatancipriani/Library/Caches/pypoetry/virtualenvs/filesharing-K7xW8qzq-py3.9/lib/python3.9/site-packages/pymongo/srv_resolver.py", line 95, in _resolve_uri
    raise ConfigurationError(str(exc))
pymongo.errors.ConfigurationError: The DNS operation timed out after 20.002588987350464 seconds
INFO:werkzeug:127.0.0.1 - - [19/Aug/2021 19:49:15] "[35m[1mPOST /send_request?request_type=Tx&file_name=s.txt&file_location=S HTTP/1.1[0m" 500 -
INFO:werkzeug:127.0.0.1 - - [19/Aug/2021 19:49:59] "GET /shutdown HTTP/1.1" 200 -
INFO:root: 2021-08-19 19:50:00 Service has stopped
INFO:werkzeug: * Running on http://127.0.0.1:5000/ (Press CTRL+C to quit)
INFO:root: 2021-08-19 19:50:42 Service Started
INFO:werkzeug:127.0.0.1 - - [19/Aug/2021 19:51:02] "GET /shutdown HTTP/1.1" 200 -
ERROR:filesharing.app:Exception on /send_request [POST]
Traceback (most recent call last):
  File "/Users/yonatancipriani/Library/Caches/pypoetry/virtualenvs/filesharing-K7xW8qzq-py3.9/lib/python3.9/site-packages/pymongo/srv_resolver.py", line 88, in _resolve_uri
    results = _resolve('_mongodb._tcp.' + self.__fqdn, 'SRV',
  File "/Users/yonatancipriani/Library/Caches/pypoetry/virtualenvs/filesharing-K7xW8qzq-py3.9/lib/python3.9/site-packages/pymongo/srv_resolver.py", line 46, in _resolve
    return resolver.resolve(*args, **kwargs)
  File "/Users/yonatancipriani/Library/Caches/pypoetry/virtualenvs/filesharing-K7xW8qzq-py3.9/lib/python3.9/site-packages/dns/resolver.py", line 1305, in resolve
    return get_default_resolver().resolve(qname, rdtype, rdclass, tcp, source,
  File "/Users/yonatancipriani/Library/Caches/pypoetry/virtualenvs/filesharing-K7xW8qzq-py3.9/lib/python3.9/site-packages/dns/resolver.py", line 1176, in resolve
    timeout = self._compute_timeout(start, lifetime)
  File "/Users/yonatancipriani/Library/Caches/pypoetry/virtualenvs/filesharing-K7xW8qzq-py3.9/lib/python3.9/site-packages/dns/resolver.py", line 997, in _compute_timeout
    raise Timeout(timeout=duration)
dns.exception.Timeout: The DNS operation timed out after 20.00204300880432 seconds

During handling of the above exception, another exception occurred:

Traceback (most recent call last):
  File "/Users/yonatancipriani/Library/Caches/pypoetry/virtualenvs/filesharing-K7xW8qzq-py3.9/lib/python3.9/site-packages/flask/app.py", line 2070, in wsgi_app
    response = self.full_dispatch_request()
  File "/Users/yonatancipriani/Library/Caches/pypoetry/virtualenvs/filesharing-K7xW8qzq-py3.9/lib/python3.9/site-packages/flask/app.py", line 1515, in full_dispatch_request
    rv = self.handle_user_exception(e)
  File "/Users/yonatancipriani/Library/Caches/pypoetry/virtualenvs/filesharing-K7xW8qzq-py3.9/lib/python3.9/site-packages/flask_restful/__init__.py", line 271, in error_router
    return original_handler(e)
  File "/Users/yonatancipriani/Library/Caches/pypoetry/virtualenvs/filesharing-K7xW8qzq-py3.9/lib/python3.9/site-packages/flask/app.py", line 1513, in full_dispatch_request
    rv = self.dispatch_request()
  File "/Users/yonatancipriani/Library/Caches/pypoetry/virtualenvs/filesharing-K7xW8qzq-py3.9/lib/python3.9/site-packages/flask/app.py", line 1499, in dispatch_request
    return self.ensure_sync(self.view_functions[rule.endpoint])(**req.view_args)
  File "/Users/yonatancipriani/PycharmProjects/fileSharing/filesharing/app.py", line 57, in send_request
    dal = mongodbDAL(request_type)
  File "/Users/yonatancipriani/PycharmProjects/fileSharing/filesharing/db/mongodbDAL.py", line 11, in __init__
    self.client = MongoClient(self.connection_string)
  File "/Users/yonatancipriani/Library/Caches/pypoetry/virtualenvs/filesharing-K7xW8qzq-py3.9/lib/python3.9/site-packages/pymongo/mongo_client.py", line 670, in __init__
    res = uri_parser.parse_uri(
  File "/Users/yonatancipriani/Library/Caches/pypoetry/virtualenvs/filesharing-K7xW8qzq-py3.9/lib/python3.9/site-packages/pymongo/uri_parser.py", line 524, in parse_uri
    nodes = dns_resolver.get_hosts()
  File "/Users/yonatancipriani/Library/Caches/pypoetry/virtualenvs/filesharing-K7xW8qzq-py3.9/lib/python3.9/site-packages/pymongo/srv_resolver.py", line 118, in get_hosts
    _, nodes = self._get_srv_response_and_hosts(True)
  File "/Users/yonatancipriani/Library/Caches/pypoetry/virtualenvs/filesharing-K7xW8qzq-py3.9/lib/python3.9/site-packages/pymongo/srv_resolver.py", line 99, in _get_srv_response_and_hosts
    results = self._resolve_uri(encapsulate_errors)
  File "/Users/yonatancipriani/Library/Caches/pypoetry/virtualenvs/filesharing-K7xW8qzq-py3.9/lib/python3.9/site-packages/pymongo/srv_resolver.py", line 95, in _resolve_uri
    raise ConfigurationError(str(exc))
pymongo.errors.ConfigurationError: The DNS operation timed out after 20.00204300880432 seconds
INFO:werkzeug:127.0.0.1 - - [19/Aug/2021 19:51:02] "[35m[1mPOST /send_request?request_type=Tx&file_name=s.txt&file_location=S HTTP/1.1[0m" 500 -
INFO:root: 2021-08-19 19:51:03 Service has stopped
INFO:werkzeug: * Running on http://127.0.0.1:5000/ (Press CTRL+C to quit)
INFO:root: 2021-08-19 19:51:09 Service Started
ERROR:filesharing.app:Exception on /send_request [POST]
Traceback (most recent call last):
  File "/Users/yonatancipriani/Library/Caches/pypoetry/virtualenvs/filesharing-K7xW8qzq-py3.9/lib/python3.9/site-packages/pymongo/srv_resolver.py", line 88, in _resolve_uri
    results = _resolve('_mongodb._tcp.' + self.__fqdn, 'SRV',
  File "/Users/yonatancipriani/Library/Caches/pypoetry/virtualenvs/filesharing-K7xW8qzq-py3.9/lib/python3.9/site-packages/pymongo/srv_resolver.py", line 46, in _resolve
    return resolver.resolve(*args, **kwargs)
  File "/Users/yonatancipriani/Library/Caches/pypoetry/virtualenvs/filesharing-K7xW8qzq-py3.9/lib/python3.9/site-packages/dns/resolver.py", line 1305, in resolve
    return get_default_resolver().resolve(qname, rdtype, rdclass, tcp, source,
  File "/Users/yonatancipriani/Library/Caches/pypoetry/virtualenvs/filesharing-K7xW8qzq-py3.9/lib/python3.9/site-packages/dns/resolver.py", line 1176, in resolve
    timeout = self._compute_timeout(start, lifetime)
  File "/Users/yonatancipriani/Library/Caches/pypoetry/virtualenvs/filesharing-K7xW8qzq-py3.9/lib/python3.9/site-packages/dns/resolver.py", line 997, in _compute_timeout
    raise Timeout(timeout=duration)
dns.exception.Timeout: The DNS operation timed out after 20.00409483909607 seconds

During handling of the above exception, another exception occurred:

Traceback (most recent call last):
  File "/Users/yonatancipriani/Library/Caches/pypoetry/virtualenvs/filesharing-K7xW8qzq-py3.9/lib/python3.9/site-packages/flask/app.py", line 2070, in wsgi_app
    response = self.full_dispatch_request()
  File "/Users/yonatancipriani/Library/Caches/pypoetry/virtualenvs/filesharing-K7xW8qzq-py3.9/lib/python3.9/site-packages/flask/app.py", line 1515, in full_dispatch_request
    rv = self.handle_user_exception(e)
  File "/Users/yonatancipriani/Library/Caches/pypoetry/virtualenvs/filesharing-K7xW8qzq-py3.9/lib/python3.9/site-packages/flask_restful/__init__.py", line 271, in error_router
    return original_handler(e)
  File "/Users/yonatancipriani/Library/Caches/pypoetry/virtualenvs/filesharing-K7xW8qzq-py3.9/lib/python3.9/site-packages/flask/app.py", line 1513, in full_dispatch_request
    rv = self.dispatch_request()
  File "/Users/yonatancipriani/Library/Caches/pypoetry/virtualenvs/filesharing-K7xW8qzq-py3.9/lib/python3.9/site-packages/flask/app.py", line 1499, in dispatch_request
    return self.ensure_sync(self.view_functions[rule.endpoint])(**req.view_args)
  File "/Users/yonatancipriani/PycharmProjects/fileSharing/filesharing/app.py", line 57, in send_request
    dal = mongodbDAL(request_type)
  File "/Users/yonatancipriani/PycharmProjects/fileSharing/filesharing/db/mongodbDAL.py", line 11, in __init__
    self.client = MongoClient(self.connection_string)
  File "/Users/yonatancipriani/Library/Caches/pypoetry/virtualenvs/filesharing-K7xW8qzq-py3.9/lib/python3.9/site-packages/pymongo/mongo_client.py", line 670, in __init__
    res = uri_parser.parse_uri(
  File "/Users/yonatancipriani/Library/Caches/pypoetry/virtualenvs/filesharing-K7xW8qzq-py3.9/lib/python3.9/site-packages/pymongo/uri_parser.py", line 524, in parse_uri
    nodes = dns_resolver.get_hosts()
  File "/Users/yonatancipriani/Library/Caches/pypoetry/virtualenvs/filesharing-K7xW8qzq-py3.9/lib/python3.9/site-packages/pymongo/srv_resolver.py", line 118, in get_hosts
    _, nodes = self._get_srv_response_and_hosts(True)
  File "/Users/yonatancipriani/Library/Caches/pypoetry/virtualenvs/filesharing-K7xW8qzq-py3.9/lib/python3.9/site-packages/pymongo/srv_resolver.py", line 99, in _get_srv_response_and_hosts
    results = self._resolve_uri(encapsulate_errors)
  File "/Users/yonatancipriani/Library/Caches/pypoetry/virtualenvs/filesharing-K7xW8qzq-py3.9/lib/python3.9/site-packages/pymongo/srv_resolver.py", line 95, in _resolve_uri
    raise ConfigurationError(str(exc))
pymongo.errors.ConfigurationError: The DNS operation timed out after 20.00409483909607 seconds
INFO:werkzeug:127.0.0.1 - - [19/Aug/2021 19:51:15] "[35m[1mPOST /send_request?request_type=Tx&file_name=s.txt&file_location=S HTTP/1.1[0m" 500 -
